<mujoco>
    <option timestep="0.00001" />
    <actuator>
        <motor gear="250" joint="shoulder_pitch" name="shoulder_pitch" ctrlrange="-100 100" ctrllimited="true"/>
        <motor gear="250" joint="shoulder_pitch2" name="shoulder_roll" ctrlrange="-100 100" ctrllimited="true"/>
    </actuator>
    <asset>
        <material name="blue" rgba="0 0 1 1" />
        <material name="green" rgba="0 1 0 1" />
        <material name="red" rgba="1 0 0 1" />
        <material name="white" rgba="1 1 1 1" />
        <material name="black" rgba="0 0 0 .5" />
    </asset>
    <worldbody>
        <geom type="plane" size="10 10 0.1" pos="0 0 -5" rgba=".9 0 0 1"  material = "white"/>
        <light diffuse=".5 .5 .5" pos="0 0 3" dir="0 0 -1" />
        <body name="link_1" pos="1 0 0" euler = "0 0 0">
            <joint name="shoulder_pitch" pos="0 0 0" axis="0 0 1" />
            <geom type="cylinder" size=".198 .165" pos="0 0 0" density="65" euler="0 0 0" material="black" />
            <geom type="box" size=".165 .165   .5" pos="0 .5 0" density="20" euler="90 0 0" material="blue" />
            <body name="link_2" pos="0 1 0" euler="0 0 0">
            <joint name="shoulder_pitch11" pos="0 0 0" axis="0 0 1" />
                <geom type="cylinder" size=".198    .165" pos="0 0 0" density="65" euler="0 0 0" material="black" />
                <geom type="box" size=".165 .165   .5" pos="-0.5 0 0" density="20" euler="90 90 0" material="blue" />
            <body name="actuator" pos="-1 0 0" euler="0 0 0">
                <joint name="shoulder_pitch12" pos="0 0 0" axis="0 0 1" />
                    <geom type="cylinder" size=".198    .165" pos="0 0 0" density="65" euler="0 0 0" material="green" />
                
                    </body>
                </body>
                </body>
        <body name="link_3" pos="-1 0 0" euler = "0 0 0">
            <joint name="shoulder_pitch2" pos="0 0 0" axis="0 0 1" />
            <geom type="cylinder" size=".198 .165" pos="0 0 0" density="65" euler="0 0 0" material="black" />
            <geom type="box" size=".165 .165   .5" pos="0 .5 0" density="20" euler="90 0 0" material="blue" />
            <body name="link_4" pos="0 1 0" euler="0 0 0">
            <joint name="shoulder_pitch22" pos="0 0 0" axis="0 0 1" />
                <geom type="cylinder" size=".198    .165" pos="0 0 0" density="65" euler="0 0 0" material="black" />
                <geom type="box" size=".165 .165   .5" pos="0.5 0 0" density="20" euler="90 -90 0" material="blue" />
            <body name="actuator2" pos="1 0 0" euler="0 0 0">
                <joint name="shoulder_pitch23" pos="0 0 0" axis="0 0 1" />
                    <geom type="cylinder" size=".198    .165" pos="0 0 0" density="65" euler="0 0 0" material="green" />
                
                    </body>
            </body>
        </body>
    </worldbody>
    <equality>
        <connect name="kinematic_link" active="true" body1="actuator" body2="actuator2" anchor="0 0 0" />
        <connect name="kinematic_link2" active="true" body1="link_4" body2="actuator" anchor="0 0 0" />
        <connect name="kinematic_link3" active="true" body1="actuator2" body2="link_2" anchor="0 0 0" />
    </equality>
    <contact>
        <exclude body1="actuator" body2="actuator2"/>
        <exclude body1="link_2" body2="link_4"/>
        <exclude body1="link_2" body2="actuator2"/>
        <exclude body1="link_2" body2="actuator"/>
        <exclude body1="link_4" body2="actuator2"/>
        <exclude body1="link_4" body2="actuator"/>
    </contact>
</mujoco>