ё <mujoco>
    <option timestep="0.00001" />
    <actuator>
        <motor gear="250" joint="shoulder_pitch" name="shoulder_pitch" ctrlrange="-100 100" ctrllimited="true"/>
        <motor gear="250" joint="shoulder_roll" name="shoulder_roll" ctrlrange="-100 100" ctrllimited="true"/>
        <motor gear="250" joint="shoulder_yaw" name="shoulder_yaw" ctrlrange="-100 100" ctrllimited="true"/>
        <motor gear="250" joint="elbow_pitch" name="elbow_pitch" ctrlrange="-100 100" ctrllimited="true"/>
        <motor gear="250" joint="end_effector" name="end_effector" ctrlrange="-100 100" ctrllimited="true"/>
    </actuator>
    <asset>
        <material name="blue" rgba="0 0 1 1" />
        <material name="green" rgba="0 1 0 1" />
        <material name="red" rgba="1 0 0 1" />
        <material name="white" rgba="1 1 1 1" />
        <material name="black" rgba="0 0 0 .5" />
    </asset>
    <worldbody>
        <geom type="plane" size="10 10 0.1" pos="0 0 -5" rgba=".9 0 0 1"  material = "white"/>
        <light diffuse=".5 .5 .5" pos="0 0 3" dir="0 0 -1" />
        <body name = "frame" pos = "0 0 0">
            <geom type="box" size="1 1 1" pos="0 0 0" euler="0 0 0" material="black" />
            <geom type="box" size=".8  .8  .8" pos="0 0 1.8" euler="0 0 0" material="black" />
        </body>
        <body name="link_1" pos=".965 0 1.8">
            <joint name="shoulder_pitch" pos="0 0 0" axis="1 0 0" />
            <geom type="cylinder" size=".198 .165" pos="0 0 0" mass="65" euler="0 90 0" material="black" />
            <body name="link_2" pos="0.363 0 0" euler="0 90 0">
                <joint name="shoulder_roll" pos="0 0 0" axis="1 0 0" />
                <geom type="cylinder" size=".198    .165" pos="0 0 0" mass="65" euler="0 90 0" material="black" />
                <body name="link_3" pos="0 0.396 0" euler="0 90 0">
                    <joint name="shoulder_yaw" pos="0 0 0" axis="0 1 0" />
                    <geom type="cylinder" size=".198 .165" pos="0 0 0" density="65" euler="90 0 0" material="black" />
                    <geom type="box" size=".05 .198   .5" pos=".2 .5 0" density="20" euler="90 0 0" material="green" />
                    <geom type="box" size=".05 .198   .5" pos="-.2 .5 0" density="20" euler="90 0 0" material="green" />
                    <geom type="cylinder" size=".198 .05" pos=".2 1 0" euler="0 90 0" material="green" />
                    <geom type="cylinder" size=".198 .05" pos="-.2 1 0" euler="0 90 0" material="green" />
                    <body name="link_4" pos="0 1 0" euler="0 90 0">
                        <joint name="elbow_pitch" pos="0 0 0" axis="0 0 1" />
                        <geom type="cylinder" size=".198 .165" pos="0 0 0" density="65" euler="0 0 0" material="black" />
                        <geom type="box" size=".165 .165   .5" pos="0 .5 0" density="20" euler="90 0 0" material="blue" />
                        <body name="link_5" pos="0 1 0" euler="0 90 0">
                            <joint name="end_effector" pos="0 0 0" axis="1 0 0" />
                            <geom type="sphere" size=".25" pos="0 0 0" euler="90 0 0" material="red" />
                        </body>

                    </body>
                </body>
            </body>
        </body>
    </worldbody>
    <equality>
    </equality>
    <contact>
    </contact>
</mujoco>